{
 "cells": [
  {
   "cell_type": "code",
   "execution_count": 2,
   "metadata": {},
   "outputs": [],
   "source": [
    "import pandas as pd\n",
    "import numpy as np\n",
    "import matplotlib.pyplot as plt\n",
    "import keras"
   ]
  },
  {
   "cell_type": "code",
   "execution_count": 5,
   "metadata": {},
   "outputs": [
    {
     "data": {
      "text/plain": [
       "(2952, 2, 7, 11)"
      ]
     },
     "execution_count": 5,
     "metadata": {},
     "output_type": "execute_result"
    }
   ],
   "source": [
    "data = np.load(\"../scooter_data.npy\")\n",
    "data.shape"
   ]
  },
  {
   "cell_type": "code",
   "execution_count": 10,
   "metadata": {},
   "outputs": [],
   "source": [
    "sequence_length = 168\n",
    "input_shape = (sequence_length,data.shape[-1])\n",
    "output_shape = 77"
   ]
  },
  {
   "cell_type": "code",
   "execution_count": 11,
   "metadata": {},
   "outputs": [
    {
     "ename": "ValueError",
     "evalue": "in user code:\n\n    File \"d:\\Anoconda\\envs\\py310\\lib\\site-packages\\keras\\engine\\training.py\", line 1160, in train_function  *\n        return step_function(self, iterator)\n    File \"d:\\Anoconda\\envs\\py310\\lib\\site-packages\\keras\\engine\\training.py\", line 1146, in step_function  **\n        outputs = model.distribute_strategy.run(run_step, args=(data,))\n    File \"d:\\Anoconda\\envs\\py310\\lib\\site-packages\\keras\\engine\\training.py\", line 1135, in run_step  **\n        outputs = model.train_step(data)\n    File \"d:\\Anoconda\\envs\\py310\\lib\\site-packages\\keras\\engine\\training.py\", line 993, in train_step\n        y_pred = self(x, training=True)\n    File \"d:\\Anoconda\\envs\\py310\\lib\\site-packages\\keras\\utils\\traceback_utils.py\", line 70, in error_handler\n        raise e.with_traceback(filtered_tb) from None\n    File \"d:\\Anoconda\\envs\\py310\\lib\\site-packages\\keras\\engine\\input_spec.py\", line 295, in assert_input_compatibility\n        raise ValueError(\n\n    ValueError: Input 0 of layer \"model\" is incompatible with the layer: expected shape=(None, 168, 11), found shape=(None, 2, 7, 11)\n",
     "output_type": "error",
     "traceback": [
      "\u001b[1;31m---------------------------------------------------------------------------\u001b[0m",
      "\u001b[1;31mValueError\u001b[0m                                Traceback (most recent call last)",
      "Cell \u001b[1;32mIn[11], line 9\u001b[0m\n\u001b[0;32m      6\u001b[0m model \u001b[38;5;241m=\u001b[39m keras\u001b[38;5;241m.\u001b[39mModel(inputs, outputs)\n\u001b[0;32m      8\u001b[0m model\u001b[38;5;241m.\u001b[39mcompile(loss \u001b[38;5;241m=\u001b[39m \u001b[38;5;124m\"\u001b[39m\u001b[38;5;124mmse\u001b[39m\u001b[38;5;124m\"\u001b[39m, metrics \u001b[38;5;241m=\u001b[39m [\u001b[38;5;124m\"\u001b[39m\u001b[38;5;124mmae\u001b[39m\u001b[38;5;124m\"\u001b[39m])\n\u001b[1;32m----> 9\u001b[0m history \u001b[38;5;241m=\u001b[39m \u001b[43mmodel\u001b[49m\u001b[38;5;241;43m.\u001b[39;49m\u001b[43mfit\u001b[49m\u001b[43m(\u001b[49m\u001b[43mdata\u001b[49m\u001b[43m,\u001b[49m\u001b[43mbatch_size\u001b[49m\u001b[38;5;241;43m=\u001b[39;49m\u001b[43m \u001b[49m\u001b[38;5;241;43m32\u001b[39;49m\u001b[43m)\u001b[49m\n",
      "File \u001b[1;32md:\\Anoconda\\envs\\py310\\lib\\site-packages\\keras\\utils\\traceback_utils.py:70\u001b[0m, in \u001b[0;36mfilter_traceback.<locals>.error_handler\u001b[1;34m(*args, **kwargs)\u001b[0m\n\u001b[0;32m     67\u001b[0m     filtered_tb \u001b[38;5;241m=\u001b[39m _process_traceback_frames(e\u001b[38;5;241m.\u001b[39m__traceback__)\n\u001b[0;32m     68\u001b[0m     \u001b[38;5;66;03m# To get the full stack trace, call:\u001b[39;00m\n\u001b[0;32m     69\u001b[0m     \u001b[38;5;66;03m# `tf.debugging.disable_traceback_filtering()`\u001b[39;00m\n\u001b[1;32m---> 70\u001b[0m     \u001b[38;5;28;01mraise\u001b[39;00m e\u001b[38;5;241m.\u001b[39mwith_traceback(filtered_tb) \u001b[38;5;28;01mfrom\u001b[39;00m \u001b[38;5;28;01mNone\u001b[39;00m\n\u001b[0;32m     71\u001b[0m \u001b[38;5;28;01mfinally\u001b[39;00m:\n\u001b[0;32m     72\u001b[0m     \u001b[38;5;28;01mdel\u001b[39;00m filtered_tb\n",
      "File \u001b[1;32m~\\AppData\\Local\\Temp\\__autograph_generated_filelxqy70_k.py:15\u001b[0m, in \u001b[0;36mouter_factory.<locals>.inner_factory.<locals>.tf__train_function\u001b[1;34m(iterator)\u001b[0m\n\u001b[0;32m     13\u001b[0m \u001b[38;5;28;01mtry\u001b[39;00m:\n\u001b[0;32m     14\u001b[0m     do_return \u001b[38;5;241m=\u001b[39m \u001b[38;5;28;01mTrue\u001b[39;00m\n\u001b[1;32m---> 15\u001b[0m     retval_ \u001b[38;5;241m=\u001b[39m ag__\u001b[38;5;241m.\u001b[39mconverted_call(ag__\u001b[38;5;241m.\u001b[39mld(step_function), (ag__\u001b[38;5;241m.\u001b[39mld(\u001b[38;5;28mself\u001b[39m), ag__\u001b[38;5;241m.\u001b[39mld(iterator)), \u001b[38;5;28;01mNone\u001b[39;00m, fscope)\n\u001b[0;32m     16\u001b[0m \u001b[38;5;28;01mexcept\u001b[39;00m:\n\u001b[0;32m     17\u001b[0m     do_return \u001b[38;5;241m=\u001b[39m \u001b[38;5;28;01mFalse\u001b[39;00m\n",
      "\u001b[1;31mValueError\u001b[0m: in user code:\n\n    File \"d:\\Anoconda\\envs\\py310\\lib\\site-packages\\keras\\engine\\training.py\", line 1160, in train_function  *\n        return step_function(self, iterator)\n    File \"d:\\Anoconda\\envs\\py310\\lib\\site-packages\\keras\\engine\\training.py\", line 1146, in step_function  **\n        outputs = model.distribute_strategy.run(run_step, args=(data,))\n    File \"d:\\Anoconda\\envs\\py310\\lib\\site-packages\\keras\\engine\\training.py\", line 1135, in run_step  **\n        outputs = model.train_step(data)\n    File \"d:\\Anoconda\\envs\\py310\\lib\\site-packages\\keras\\engine\\training.py\", line 993, in train_step\n        y_pred = self(x, training=True)\n    File \"d:\\Anoconda\\envs\\py310\\lib\\site-packages\\keras\\utils\\traceback_utils.py\", line 70, in error_handler\n        raise e.with_traceback(filtered_tb) from None\n    File \"d:\\Anoconda\\envs\\py310\\lib\\site-packages\\keras\\engine\\input_spec.py\", line 295, in assert_input_compatibility\n        raise ValueError(\n\n    ValueError: Input 0 of layer \"model\" is incompatible with the layer: expected shape=(None, 168, 11), found shape=(None, 2, 7, 11)\n"
     ]
    }
   ],
   "source": [
    "# a simple LSTM-based model\n",
    "from keras import layers\n",
    "inputs = keras.Input(shape = (input_shape))\n",
    "x = layers.LSTM(16)(inputs)\n",
    "outputs = layers.Dense(output_shape)(x)\n",
    "model = keras.Model(inputs, outputs)\n",
    "\n",
    "model.compile(loss = \"mse\", metrics = [\"mae\"])\n",
    "history = model.fit(data,batch_size= 32)"
   ]
  },
  {
   "cell_type": "code",
   "execution_count": null,
   "metadata": {},
   "outputs": [],
   "source": []
  }
 ],
 "metadata": {
  "kernelspec": {
   "display_name": "py310",
   "language": "python",
   "name": "python3"
  },
  "language_info": {
   "codemirror_mode": {
    "name": "ipython",
    "version": 3
   },
   "file_extension": ".py",
   "mimetype": "text/x-python",
   "name": "python",
   "nbconvert_exporter": "python",
   "pygments_lexer": "ipython3",
   "version": "3.10.13"
  }
 },
 "nbformat": 4,
 "nbformat_minor": 2
}
